2020-03-01 12:51:23,539 [ERROR]  Exception occurred while handling uri: 'http://localhost:5005/visualization.html'
Traceback (most recent call last):
  File "/Users/Mariam/.pyenv/versions/3.6.5/lib/python3.6/site-packages/sanic/app.py", line 893, in handle_request
    handler, args, kwargs, uri = self.router.get(request)
  File "/Users/Mariam/.pyenv/versions/3.6.5/lib/python3.6/site-packages/sanic/router.py", line 407, in get
    return self._get(request.path, request.method, "")
  File "/Users/Mariam/.pyenv/versions/3.6.5/lib/python3.6/site-packages/sanic/router.py", line 469, in _get
    raise NotFound("Requested URL {} not found".format(url))
sanic.exceptions.NotFound: Requested URL /visualization.html not found
